<?xml version="1.0" encoding="utf-8"?>
<!-- This URDF was automatically created by SolidWorks to URDF Exporter! Originally created by Stephen Brawner (brawner@gmail.com) 
     Commit Version: 1.5.1-0-g916b5db  Build Version: 1.5.7152.31018
     For more information, please see http://wiki.ros.org/sw_urdf_exporter -->
<robot
  name="assembly">
  <link
    name="base_link">
    <inertial>
      <origin
        xyz="0.0276418278157166 -0.472599056033966 0.0312550060354526"
        rpy="0 0 0" />
      <mass
        value="2.26299534521545" />
      <inertia
        ixx="0.0236090944163617"
        ixy="4.20123862892758E-19"
        ixz="3.29690604315033E-08"
        iyy="0.0191899669560079"
        iyz="-1.27406422046969E-05"
        izz="0.0424983502674055" />
    </inertial>
    <visual>
      <origin
        xyz="0 0 0"
        rpy="0 0 0" />
      <geometry>
        <mesh
          filename="package://assembly/meshes/base_link.STL" />
      </geometry>
      <material
        name="">
        <color
          rgba="0.752941176470588 0.752941176470588 0.752941176470588 1" />
      </material>
    </visual>
    <collision>
      <origin
        xyz="0 0 0"
        rpy="0 0 0" />
      <geometry>
        <mesh
          filename="package://assembly/meshes/base_link.STL" />
      </geometry>
    </collision>
  </link>
  <link
    name="Front">
    <inertial>
      <origin
        xyz="0.74891 0.028658 -0.0076879"
        rpy="0 0 0" />
      <mass
        value="0.23852" />
      <inertia
        ixx="0.00016726"
        ixy="3.6036E-08"
        ixz="1.4132E-08"
        iyy="0.00029897"
        iyz="4.4926E-08"
        izz="0.00016727" />
    </inertial>
    <visual>
      <origin
        xyz="0 0 0"
        rpy="0 0 0" />
      <geometry>
        <mesh
          filename="package://assembly/meshes/Front.STL" />
      </geometry>
      <material
        name="">
        <color
          rgba="1 1 1 1" />
      </material>
    </visual>
    <collision>
      <origin
        xyz="0 0 0"
        rpy="0 0 0" />
      <geometry>
        <mesh
          filename="package://assembly/meshes/Front.STL" />
      </geometry>
    </collision>
  </link>
  <joint
    name="F"
    type="continuous">
    <origin
      xyz="0 0 0"
      rpy="0 0 -1.5708" />
    <parent
      link="base_link" />
    <child
      link="Front" />
    <axis
      xyz="0 1 0" />
    <limit
      effort="0"
      velocity="7" />
  </joint>
  <link
    name="Left">
    <inertial>
      <origin
        xyz="0.4726 0.027642 0.031255"
        rpy="0 0 0" />
      <mass
        value="2.263" />
      <inertia
        ixx="0.01919"
        ixy="-5.0445E-19"
        ixz="1.2741E-05"
        iyy="0.023609"
        iyz="3.2969E-08"
        izz="0.042498" />
    </inertial>
    <visual>
      <origin
        xyz="0 0 0"
        rpy="0 0 0" />
      <geometry>
        <mesh
          filename="package://assembly/meshes/Left.STL" />
      </geometry>
      <material
        name="">
        <color
          rgba="0.75294 0.75294 0.75294 1" />
      </material>
    </visual>
    <collision>
      <origin
        xyz="0 0 0"
        rpy="0 0 0" />
      <geometry>
        <mesh
          filename="package://assembly/meshes/Left.STL" />
      </geometry>
    </collision>
  </link>
  <joint
    name="L"
    type="continuous">
    <origin
      xyz="0 0 0"
      rpy="0 0 -1.5708" />
    <parent
      link="base_link" />
    <child
      link="Left" />
    <axis
      xyz="0 1 0" />
    <limit
      effort="0"
      velocity="7" />
  </joint>
  <link
    name="Right">
    <inertial>
      <origin
        xyz="0 0 0"
        rpy="0 0 0" />
      <mass
        value="0" />
      <inertia
        ixx="0"
        ixy="0"
        ixz="0"
        iyy="0"
        iyz="0"
        izz="0" />
    </inertial>
    <visual>
      <origin
        xyz="0 0 0"
        rpy="0 0 0" />
      <geometry>
        <mesh
          filename="package://assembly/meshes/Right.STL" />
      </geometry>
      <material
        name="">
        <color
          rgba="1 1 1 1" />
      </material>
    </visual>
    <collision>
      <origin
        xyz="0 0 0"
        rpy="0 0 0" />
      <geometry>
        <mesh
          filename="package://assembly/meshes/Right.STL" />
      </geometry>
    </collision>
  </link>
  <joint
    name="R"
    type="continuous">
    <origin
      xyz="0 0 0"
      rpy="0 0 -1.5708" />
    <parent
      link="base_link" />
    <child
      link="Right" />
    <axis
      xyz="0 1 0" />
    <limit
      effort="0"
      velocity="7" />
  </joint>
</robot>